Workbook

Sheet Resumen
A1: RESUMEN DE INDICADORES
A2: Calculado. No editar. Estadístico principal: MEDIANA.
A4: IB-1 agregado · medición previa (forma A)
B5: n | C5: Mediana (s) | D5: Q1 (s) | E5: Q3 (s) | F5: Media (s) | G5: % censurado
A6: Todos los casos | B6: =COUNT(Registro!$X$2:$X$65) -> 64 | C6: =IFERROR(MEDIAN(Registro!$X$2:$X$65),"—") -> 109 | D6: =IFERROR(QUARTILE(Registro!$X$2:$X$65,1),"—") -> 48.25 | E6: =IFERROR(QUARTILE(Registro!$X$2:$X$65,3),"—") -> 222.75 | F6: =IFERROR(AVERAGE(Registro!$X$2:$X$65),"—") -> 140.96875 | G6: =IFERROR(COUNTIFS(Registro!$C$2:$C$65,"Pre",Registro!$R$2:$R$65,"Sí",Registro!$J$2:$J$65,"Sí")/COUNTIFS(Registro!$C$2:$C$65,"Pre",Registro!$R$2:$R$65,"Sí"),"—") -> 0.203125
A8: IB-1 por tipo de caso · medición previa
B9: n | C9: Mediana (s) | D9: Q1 (s) | E9: Q3 (s) | F9: Media (s) | G9: % censurado
A10: Tipo A · origen único | B10: =COUNT(Registro!$T$2:$T$65) -> 16 | C10: =IFERROR(MEDIAN(Registro!$T$2:$T$65),"—") -> 26 | D10: =IFERROR(QUARTILE(Registro!$T$2:$T$65,1),"—") -> 19.5 | E10: =IFERROR(QUARTILE(Registro!$T$2:$T$65,3),"—") -> 30.25 | F10: =IFERROR(AVERAGE(Registro!$T$2:$T$65),"—") -> 26.125 | G10: =IFERROR(COUNTIFS(Registro!$C$2:$C$65,"Pre",Registro!$R$2:$R$65,"Sí",Registro!$H$2:$H$65,"A",Registro!$J$2:$J$65,"Sí")/COUNTIFS(Registro!$C$2:$C$65,"Pre",Registro!$R$2:$R$65,"Sí",Registro!$H$2:$H$65,"A"),"—") -> 0
A11: Tipo B · conflicto de precedencia | B11: =COUNT(Registro!$U$2:$U$65) -> 16 | C11: =IFERROR(MEDIAN(Registro!$U$2:$U$65),"—") -> 104 | D11: =IFERROR(QUARTILE(Registro!$U$2:$U$65,1),"—") -> 79.25 | E11: =IFERROR(QUARTILE(Registro!$U$2:$U$65,3),"—") -> 130.75 | F11: =IFERROR(AVERAGE(Registro!$U$2:$U$65),"—") -> 103.75 | G11: =IFERROR(COUNTIFS(Registro!$C$2:$C$65,"Pre",Registro!$R$2:$R$65,"Sí",Registro!$H$2:$H$65,"B",Registro!$J$2:$J$65,"Sí")/COUNTIFS(Registro!$C$2:$C$65,"Pre",Registro!$R$2:$R$65,"Sí",Registro!$H$2:$H$65,"B"),"—") -> 0
A12: Tipo C · arreglo reemplazado | B12: =COUNT(Registro!$V$2:$V$65) -> 16 | C12: =IFERROR(MEDIAN(Registro!$V$2:$V$65),"—") -> 177 | D12: =IFERROR(QUARTILE(Registro!$V$2:$V$65,1),"—") -> 121.5 | E12: =IFERROR(QUARTILE(Registro!$V$2:$V$65,3),"—") -> 222.75 | F12: =IFERROR(AVERAGE(Registro!$V$2:$V$65),"—") -> 183.625 | G12: =IFERROR(COUNTIFS(Registro!$C$2:$C$65,"Pre",Registro!$R$2:$R$65,"Sí",Registro!$H$2:$H$65,"C",Registro!$J$2:$J$65,"Sí")/COUNTIFS(Registro!$C$2:$C$65,"Pre",Registro!$R$2:$R$65,"Sí",Registro!$H$2:$H$65,"C"),"—") -> 0.1875
A13: Tipo D · valor no declarado | B13: =COUNT(Registro!$W$2:$W$65) -> 16 | C13: =IFERROR(MEDIAN(Registro!$W$2:$W$65),"—") -> 300 | D13: =IFERROR(QUARTILE(Registro!$W$2:$W$65,1),"—") -> 236.75 | E13: =IFERROR(QUARTILE(Registro!$W$2:$W$65,3),"—") -> 300 | F13: =IFERROR(AVERAGE(Registro!$W$2:$W$65),"—") -> 250.375 | G13: =IFERROR(COUNTIFS(Registro!$C$2:$C$65,"Pre",Registro!$R$2:$R$65,"Sí",Registro!$H$2:$H$65,"D",Registro!$J$2:$J$65,"Sí")/COUNTIFS(Registro!$C$2:$C$65,"Pre",Registro!$R$2:$R$65,"Sí",Registro!$H$2:$H$65,"D"),"—") -> 0.625
A14: Para el tipo D, IB-1 no es interpretable si la censura es alta: informar acierto y no resueltas.
A16: IB-2 · resultado por tipo de caso · medición previa
B17: % correcta | C17: % incorrecta | D17: % no resuelta | E17: % no correcta
A18: Tipo A · origen único | B18: =IFERROR(COUNTIFS(Registro!$C$2:$C$65,"Pre",Registro!$R$2:$R$65,"Sí",Registro!$H$2:$H$65,"A",Registro!$M$2:$M$65,"Correcta")/COUNTIFS(Registro!$C$2:$C$65,"Pre",Registro!$R$2:$R$65,"Sí",Registro!$H$2:$H$65,"A"),"—") -> 0.875 | C18: =IFERROR(COUNTIFS(Registro!$C$2:$C$65,"Pre",Registro!$R$2:$R$65,"Sí",Registro!$H$2:$H$65,"A",Registro!$M$2:$M$65,"Incorrecta")/COUNTIFS(Registro!$C$2:$C$65,"Pre",Registro!$R$2:$R$65,"Sí",Registro!$H$2:$H$65,"A"),"—") -> 0.125 | D18: =IFERROR(COUNTIFS(Registro!$C$2:$C$65,"Pre",Registro!$R$2:$R$65,"Sí",Registro!$H$2:$H$65,"A",Registro!$M$2:$M$65,"No resuelta")/COUNTIFS(Registro!$C$2:$C$65,"Pre",Registro!$R$2:$R$65,"Sí",Registro!$H$2:$H$65,"A"),"—") -> 0 | E18: =IFERROR(C18+D18,"—") -> 0.125
A19: Tipo B · conflicto de precedencia | B19: =IFERROR(COUNTIFS(Registro!$C$2:$C$65,"Pre",Registro!$R$2:$R$65,"Sí",Registro!$H$2:$H$65,"B",Registro!$M$2:$M$65,"Correcta")/COUNTIFS(Registro!$C$2:$C$65,"Pre",Registro!$R$2:$R$65,"Sí",Registro!$H$2:$H$65,"B"),"—") -> 0.5625 | C19: =IFERROR(COUNTIFS(Registro!$C$2:$C$65,"Pre",Registro!$R$2:$R$65,"Sí",Registro!$H$2:$H$65,"B",Registro!$M$2:$M$65,"Incorrecta")/COUNTIFS(Registro!$C$2:$C$65,"Pre",Registro!$R$2:$R$65,"Sí",Registro!$H$2:$H$65,"B"),"—") -> 0.4375 | D19: =IFERROR(COUNTIFS(Registro!$C$2:$C$65,"Pre",Registro!$R$2:$R$65,"Sí",Registro!$H$2:$H$65,"B",Registro!$M$2:$M$65,"No resuelta")/COUNTIFS(Registro!$C$2:$C$65,"Pre",Registro!$R$2:$R$65,"Sí",Registro!$H$2:$H$65,"B"),"—") -> 0 | E19: =IFERROR(C19+D19,"—") -> 0.4375
A20: Tipo C · arreglo reemplazado | B20: =IFERROR(COUNTIFS(Registro!$C$2:$C$65,"Pre",Registro!$R$2:$R$65,"Sí",Registro!$H$2:$H$65,"C",Registro!$M$2:$M$65,"Correcta")/COUNTIFS(Registro!$C$2:$C$65,"Pre",Registro!$R$2:$R$65,"Sí",Registro!$H$2:$H$65,"C"),"—") -> 0.3125 | C20: =IFERROR(COUNTIFS(Registro!$C$2:$C$65,"Pre",Registro!$R$2:$R$65,"Sí",Registro!$H$2:$H$65,"C",Registro!$M$2:$M$65,"Incorrecta")/COUNTIFS(Registro!$C$2:$C$65,"Pre",Registro!$R$2:$R$65,"Sí",Registro!$H$2:$H$65,"C"),"—") -> 0.5 | D20: =IFERROR(COUNTIFS(Registro!$C$2:$C$65,"Pre",Registro!$R$2:$R$65,"Sí",Registro!$H$2:$H$65,"C",Registro!$M$2:$M$65,"No resuelta")/COUNTIFS(Registro!$C$2:$C$65,"Pre",Registro!$R$2:$R$65,"Sí",Registro!$H$2:$H$65,"C"),"—") -> 0.1875 | E20: =IFERROR(C20+D20,"—") -> 0.6875
A21: Tipo D · valor no declarado | B21: =IFERROR(COUNTIFS(Registro!$C$2:$C$65,"Pre",Registro!$R$2:$R$65,"Sí",Registro!$H$2:$H$65,"D",Registro!$M$2:$M$65,"Correcta")/COUNTIFS(Registro!$C$2:$C$65,"Pre",Registro!$R$2:$R$65,"Sí",Registro!$H$2:$H$65,"D"),"—") -> 0 | C21: =IFERROR(COUNTIFS(Registro!$C$2:$C$65,"Pre",Registro!$R$2:$R$65,"Sí",Registro!$H$2:$H$65,"D",Registro!$M$2:$M$65,"Incorrecta")/COUNTIFS(Registro!$C$2:$C$65,"Pre",Registro!$R$2:$R$65,"Sí",Registro!$H$2:$H$65,"D"),"—") -> 0.375 | D21: =IFERROR(COUNTIFS(Registro!$C$2:$C$65,"Pre",Registro!$R$2:$R$65,"Sí",Registro!$H$2:$H$65,"D",Registro!$M$2:$M$65,"No resuelta")/COUNTIFS(Registro!$C$2:$C$65,"Pre",Registro!$R$2:$R$65,"Sí",Registro!$H$2:$H$65,"D"),"—") -> 0.625 | E21: =IFERROR(C21+D21,"—") -> 1
A22: Total | B22: =IFERROR(COUNTIFS(Registro!$C$2:$C$65,"Pre",Registro!$R$2:$R$65,"Sí",Registro!$M$2:$M$65,"Correcta")/COUNTIFS(Registro!$C$2:$C$65,"Pre",Registro!$R$2:$R$65,"Sí"),"—") -> 0.4375 | C22: =IFERROR(COUNTIFS(Registro!$C$2:$C$65,"Pre",Registro!$R$2:$R$65,"Sí",Registro!$M$2:$M$65,"Incorrecta")/COUNTIFS(Registro!$C$2:$C$65,"Pre",Registro!$R$2:$R$65,"Sí"),"—") -> 0.359375 | D22: =IFERROR(COUNTIFS(Registro!$C$2:$C$65,"Pre",Registro!$R$2:$R$65,"Sí",Registro!$M$2:$M$65,"No resuelta")/COUNTIFS(Registro!$C$2:$C$65,"Pre",Registro!$R$2:$R$65,"Sí"),"—") -> 0.203125 | E22: =IFERROR(C22+D22,"—") -> 0.5625
A23: «% no correcta» = incorrecta + no resuelta. IB-2 a secas excluye las no resueltas, que se concentran en el tipo D: informar solo incorrectas subestima la línea de base.
A25: IB-3 · archivos distintos por consulta · medición previa
A26: Mediana de archivos distintos | B26: =IFERROR(MEDIAN(Registro!$AE$2:$AE$65),"—") -> 3
A27: Máximo | B27: =IFERROR(MAX(Registro!$AE$2:$AE$65),"—") -> 6
A28: Consultas con uso del comando de configuración resuelta | B28: =IFERROR(COUNTIFS(Registro!$C$2:$C$65,"Pre",Registro!$R$2:$R$65,"Sí",Registro!$O$2:$O$65,"Sí")/COUNTIFS(Registro!$C$2:$C$65,"Pre",Registro!$R$2:$R$65,"Sí"),"—") -> 0.46875
A29: Intentos de consulta a un modelo de lenguaje (registrados, no admitidos) | B29: =COUNTIFS(Registro!$C$2:$C$65,"Pre",Registro!$R$2:$R$65,"Sí",Registro!$Q$2:$Q$65,"Sí") -> 4
A31: Control de covariable · conocimiento de los comandos nativos
B32: n | C32: Mediana (s)
A33: Conoce los comandos | B33: =COUNT(Registro!$Z$2:$Z$65) -> 16 | C33: =IFERROR(MEDIAN(Registro!$Z$2:$Z$65),"—") -> 81.5
A34: Los conoce parcialmente | B34: =COUNT(Registro!$AA$2:$AA$65) -> 16 | C34: =IFERROR(MEDIAN(Registro!$AA$2:$AA$65),"—") -> 107
A35: No los conoce | B35: =COUNT(Registro!$AB$2:$AB$65) -> 32 | C35: =IFERROR(MEDIAN(Registro!$AB$2:$AB$65),"—") -> 153.5
A40: Derivación del criterio de éxito · apartado I.3.4
A41: Línea de base IB-1 (mediana, forma A) | B41: =C6 -> 109
A42: Valor objetivo IB-1 — umbral de interacción (s) | B42: 2
A43: Reducción comprometida | B43: =IFERROR(1-B42/B41,"—") -> 0.98165138
A44: Línea de base IB-2 (proporción de incorrectas) | B44: =C22 -> 0.359375
A45: Línea de base IB-2 ampliada (proporción de no correctas) | B45: =E22 -> 0.5625
A46: Valor objetivo IB-2 | B46: 0
A47: Las dos celdas amarillas son los compromisos declarados en I.3. El resto se deriva del Registro.
A49: Comparación previa y posterior · protocolo del OE-4, noviembre
B50: n | C50: Mediana (s) | D50: % incorrectas | E50: % no correctas
...

Sheet Sujetos
A1: Código | B1: Nombre y apellido | C1: Rol | D1: Organización | E1: Canal de contacto | F1: Fecha sesión Pre | G1: Fecha sesión Post | H1: Consentimiento firmado | I1: Meses de uso de OpenCode | J1: Meses de uso de agentes | K1: Conoce cmd. nativos | L1: Elementos en su ámbito global | M1: Consultas por semana (F) | N1: Instalación usada en la sesión
A2: SUJ-01 | B2: Santiago Nuñez | C2: Software Developer | D2: Estudiante | E2: Presencial | F2: 46258 | H2: Si | I2: 8 | J2: 10 | K2: Sí | L2: 6 | M2: 3 | N2: Maquina Virtual
A3: SUJ-02 | B3: Fabricio Caceres | C3: Estudiante avanzado | D3: Estudiante | E3: Presencial | F3: 46259 | H3: Si | I3: 5 | J3: 10 | K3: No | L3: 2 | M3: 1 | N3: Maquina Virtual
A4: SUJ-03 | B4: Valeria Areco | C4: Ingenieria en Informatica | D4: Emsa | E4: Presencial | F4: 46260 | H4: Si | I4: 0 | J4: 6 | K4: No | L4: 0 | M4: 0 | N4: Maquina Virtual
A5: SUJ-04 | B5: Alejo Sanabria | C5: Desarrollador frontend | D5: Estudiante | E5: Presencial | F5: 46261 | H5: Si | I5: 12 | J5: 12 | K5: Sí | L5: 9 | M5: 5 | N5: Maquina Virtual
A6: SUJ-05 | B6: Lautaro Geneyro | C6: Estudiante avanzado | D6: Estudiante | E6: Presencial | F6: 46262 | H6: Si | I6: 1 | J6: 2 | K6: No | L6: 1 | M6: 1 | N6: Maquina Virtual
A7: SUJ-06 | B7: Emiliano Zubi | C7: Estudiante avanzado | D7: Estudiante | E7: Presencial | F7: 46263 | H7: Si | I7: 5 | J7: 3 | K7: Parcial | L7: 4 | M7: 2 | N7: Maquina Virtual
A8: SUJ-07 | B8: Kholer emily | C8: Estudiante avanzado | D8: Estudiante | E8: Presencial | F8: 46264 | H8: Si | I8: 1 | J8: 2 | K8: No | L8: 0 | M8: 0 | N8: Maquina Virtual
A9: SUJ-08 | B9: Matias Fleitas | C9: Estudiante avanzado | D9: Estudiante | E9: Presencial | F9: 46265 | H9: Si | I9: 3 | J9: 3 | K9: Parcial | L9: 5 | M9: 2 | N9: Maquina Virtual

Sheet Registro
A1: Sesión | B1: Sujeto | C1: Momento | D1: Forma | E1: Fecha | F1: Posición | G1: Caso | H1: Tipo | I1: Tiempo (s) | J1: Censurado | K1: Resp. valor | L1: Resp. origen | M1: Resultado | N1: Archivos distintos | O1: Usó cmd. | P1: Conoce cmd. nativos | Q1: Consultó LLM | R1: Caso válido | T1: t_pre_A | U1: t_pre_B | V1: t_pre_C | W1: t_pre_D | X1: t_pre | Y1: t_post | Z1: t_cmd_si | AA1: t_cmd_parcial | AB1: t_cmd_no | AC1: t_pos14 | AD1: t_pos58 | AE1: f_pre | AG1: (cálculo — no editar)
A2: S-01 | B2: SUJ-01 | C2: Pre | D2: A | E2: 46258 | F2: 1 | G2: 01 | H2: A | I2: 27 | J2: No | K2: MODELO-A-DOCUMENTADOR | L2: proyecto-alfa/opencode.json | M2: Correcta | N2: 1 | O2: Sí | P2: Sí | Q2: No | R2: Sí | T2: =IF(AND(AND($C2="Pre",$R2="Sí"),$H2="A"),$I2,"") -> 27 | U2: =IF(AND(AND($C2="Pre",$R2="Sí"),$H2="B"),$I2,"") | V2: =IF(AND(AND($C2="Pre",$R2="Sí"),$H2="C"),$I2,"") | W2: =IF(AND(AND($C2="Pre",$R2="Sí"),$H2="D"),$I2,"") | X2: =IF(AND($C2="Pre",$R2="Sí"),$I2,"") -> 27 | Y2: =IF(AND($C2="Post",$R2="Sí"),$I2,"") | Z2: =IF(AND(AND($C2="Pre",$R2="Sí"),$P2="Sí"),$I2,"") -> 27 | AA2: =IF(AND(AND($C2="Pre",$R2="Sí"),$P2="Parcial"),$I2,"") | AB2: =IF(AND(AND($C2="Pre",$R2="Sí"),$P2="No"),$I2,"") | AC2: =IF(AND(AND($C2="Pre",$R2="Sí"),$F2<=4),$I2,"") -> 27 | AD2: =IF(AND(AND($C2="Pre",$R2="Sí"),$F2>=5),$I2,"") | AE2: =IF(AND($C2="Pre",$R2="Sí"),$N2,"") -> 1
A3: S-01 | B3: SUJ-01 | C3: Pre | D3: A | E3: 46258 | F3: 2 | G3: 03 | H3: B | I3: 74 | J3: No | K3: MODELO-A-REVISOR-ALFA | L3: proyecto-alfa/opencode.json | M3: Correcta | N3: 2 | O3: Sí | P3: Sí | Q3: No | R3: Sí | T3: =IF(AND(AND($C3="Pre",$R3="Sí"),$H3="A"),$I3,"") | U3: =IF(AND(AND($C3="Pre",$R3="Sí"),$H3="B"),$I3,"") -> 74 | V3: =IF(AND(AND($C3="Pre",$R3="Sí"),$H3="C"),$I3,"") | W3: =IF(AND(AND($C3="Pre",$R3="Sí"),$H3="D"),$I3,"") | X3: =IF(AND($C3="Pre",$R3="Sí"),$I3,"") -> 74 | Y3: =IF(AND($C3="Post",$R3="Sí"),$I3,"") | Z3: =IF(AND(AND($C3="Pre",$R3="Sí"),$P3="Sí"),$I3,"") -> 74 | AA3: =IF(AND(AND($C3="Pre",$R3="Sí"),$P3="Parcial"),$I3,"") | AB3: =IF(AND(AND($C3="Pre",$R3="Sí"),$P3="No"),$I3,"") | AC3: =IF(AND(AND($C3="Pre",$R3="Sí"),$F3<=4),$I3,"") -> 74 | AD3: =IF(AND(AND($C3="Pre",$R3="Sí"),$F3>=5),$I3,"") | AE3: =IF(AND($C3="Pre",$R3="Sí"),$N3,"") -> 2
A4: S-01 | B4: SUJ-01 | C4: Pre | D4: A | E4: 46258 | F4: 3 | G4: 05 | H4: C | I4: 144 | J4: No | K4: solo AGENTS.md | L4: proyecto-alfa/opencode.json | M4: Correcta | N4: 3 | O4: Sí | P4: Sí | Q4: No | R4: Sí | T4: =IF(AND(AND($C4="Pre",$R4="Sí"),$H4="A"),$I4,"") | U4: =IF(AND(AND($C4="Pre",$R4="Sí"),$H4="B"),$I4,"") | V4: =IF(AND(AND($C4="Pre",$R4="Sí"),$H4="C"),$I4,"") -> 144 | W4: =IF(AND(AND($C4="Pre",$R4="Sí"),$H4="D"),$I4,"") | X4: =IF(AND($C4="Pre",$R4="Sí"),$I4,"") -> 144 | Y4: =IF(AND($C4="Post",$R4="Sí"),$I4,"") | Z4: =IF(AND(AND($C4="Pre",$R4="Sí"),$P4="Sí"),$I4,"") -> 144 | AA4: =IF(AND(AND($C4="Pre",$R4="Sí"),$P4="Parcial"),$I4,"") | AB4: =IF(AND(AND($C4="Pre",$R4="Sí"),$P4="No"),$I4,"") | AC4: =IF(AND(AND($C4="Pre",$R4="Sí"),$F4<=4),$I4,"") -> 144 | AD4: =IF(AND(AND($C4="Pre",$R4="Sí"),$F4>=5),$I4,"") | AE4: =IF(AND($C4="Pre",$R4="Sí"),$N4,"") -> 3
A5: S-01 | B5: SUJ-01 | C5: Pre | D5: A | E5: 46258 | F5: 4 | G5: 07 | H5: D | I5: 300 | J5: Sí | K5: — | L5: — | M5: No resuelta | N5: 3 | O5: Sí | P5: Sí | Q5: No | R5: Sí | T5: =IF(AND(AND($C5="Pre",$R5="Sí"),$H5="A"),$I5,"") | U5: =IF(AND(AND($C5="Pre",$R5="Sí"),$H5="B"),$I5,"") | V5: =IF(AND(AND($C5="Pre",$R5="Sí"),$H5="C"),$I5,"") | W5: =IF(AND(AND($C5="Pre",$R5="Sí"),$H5="D"),$I5,"") -> 300 | X5: =IF(AND($C5="Pre",$R5="Sí"),$I5,"") -> 300 | Y5: =IF(AND($C5="Post",$R5="Sí"),$I5,"") | Z5: =IF(AND(AND($C5="Pre",$R5="Sí"),$P5="Sí"),$I5,"") -> 300 | AA5: =IF(AND(AND($C5="Pre",$R5="Sí"),$P5="Parcial"),$I5,"") | AB5: =IF(AND(AND($C5="Pre",$R5="Sí"),$P5="No"),$I5,"") | AC5: =IF(AND(AND($C5="Pre",$R5="Sí"),$F5<=4),$I5,"") -> 300 | AD5: =IF(AND(AND($C5="Pre",$R5="Sí"),$F5>=5),$I5,"") | AE5: =IF(AND($C5="Pre",$R5="Sí"),$N5,"") -> 3
A6: S-01 | B6: SUJ-01 | C6: Pre | D6: A | E6: 46258 | F6: 5 | G6: 02 | H6: A | I6: 17 | J6: No | K6: MODELO-A-PROBADOR | L6: configuración global | M6: Correcta | N6: 1 | O6: Sí | P6: Sí | Q6: No | R6: Sí | T6: =IF(AND(AND($C6="Pre",$R6="Sí"),$H6="A"),$I6,"") -> 17 | U6: =IF(AND(AND($C6="Pre",$R6="Sí"),$H6="B"),$I6,"") | V6: =IF(AND(AND($C6="Pre",$R6="Sí"),$H6="C"),$I6,"") | W6: =IF(AND(AND($C6="Pre",$R6="Sí"),$H6="D"),$I6,"") | X6: =IF(AND($C6="Pre",$R6="Sí"),$I6,"") -> 17 | Y6: =IF(AND($C6="Post",$R6="Sí"),$I6,"") | Z6: =IF(AND(AND($C6="Pre",$R6="Sí"),$P6="Sí"),$I6,"") -> 17 | AA6: =IF(AND(AND($C6="Pre",$R6="Sí"),$P6="Parcial"),$I6,"") | AB6: =IF(AND(AND($C6="Pre",$R6="Sí"),$P6="No"),$I6,"") | AC6: =IF(AND(AND($C6="Pre",$R6="Sí"),$F6<=4),$I6,"") | AD6: =IF(AND(AND($C6="Pre",$R6="Sí"),$F6>=5),$I6,"") -> 17 | AE6: =IF(AND($C6="Pre",$R6="Sí"),$N6,"") -> 1
A7: S-01 | B7: SUJ-01 | C7: Pre | D7: A | E7: 46258 | F7: 6 | G7: 04 | H7: B | I7: 58 | J7: No | K7: MODELO-A-REFACT-PAGOS | L7: proyecto-alfa/opencode.json | M7: Incorrecta | N7: 2 | O7: Sí | P7: Sí | Q7: No | R7: Sí | T7: =IF(AND(AND($C7="Pre",$R7="Sí"),$H7="A"),$I7,"") | U7: =IF(AND(AND($C7="Pre",$R7="Sí"),$H7="B"),$I7,"") -> 58 | V7: =IF(AND(AND($C7="Pre",$R7="Sí"),$H7="C"),$I7,"") | W7: =IF(AND(AND($C7="Pre",$R7="Sí"),$H7="D"),$I7,"") | X7: =IF(AND($C7="Pre",$R7="Sí"),$I7,"") -> 58 | Y7: =IF(AND($C7="Post",$R7="Sí"),$I7,"") | Z7: =IF(AND(AND($C7="Pre",$R7="Sí"),$P7="Sí"),$I7,"") -> 58 | AA7: =IF(AND(AND($C7="Pre",$R7="Sí"),$P7="Parcial"),$I7,"") | AB7: =IF(AND(AND($C7="Pre",$R7="Sí"),$P7="No"),$I7,"") | AC7: =IF(AND(AND($C7="Pre",$R7="Sí"),$F7<=4),$I7,"") | AD7: =IF(AND(AND($C7="Pre",$R7="Sí"),$F7>=5),$I7,"") -> 58 | AE7: =IF(AND($C7="Pre",$R7="Sí"),$N7,"") -> 2
A8: S-01 | B8: SUJ-01 | C8: Pre | D8: A | E8: 46258 | F8: 7 | G8: 06 | H8: C | I8: 108 | J8: No | K8: sí, está vigente | L8: se suma a la del proyecto | M8: Incorrecta | N8: 5 | O8: Sí | P8: Sí | Q8: No | R8: Sí | T8: =IF(AND(AND($C8="Pre",$R8="Sí"),$H8="A"),$I8,"") | U8: =IF(AND(AND($C8="Pre",$R8="Sí"),$H8="B"),$I8,"") | V8: =IF(AND(AND($C8="Pre",$R8="Sí"),$H8="C"),$I8,"") -> 108 | W8: =IF(AND(AND($C8="Pre",$R8="Sí"),$H8="D"),$I8,"") | X8: =IF(AND($C8="Pre",$R8="Sí"),$I8,"") -> 108 | Y8: =IF(AND($C8="Post",$R8="Sí"),$I8,"") | Z8: =IF(AND(AND($C8="Pre",$R8="Sí"),$P8="Sí"),$I8,"") -> 108 | AA8: =IF(AND(AND($C8="Pre",$R8="Sí"),$P8="Parcial"),$I8,"") | AB8: =IF(AND(AND($C8="Pre",$R8="Sí"),$P8="No"),$I8,"") | AC8: =IF(AND(AND($C8="Pre",$R8="Sí"),$F8<=4),$I8,"") | AD8: =IF(AND(AND($C8="Pre",$R8="Sí"),$F8>=5),$I8,"") -> 108 | AE8: =IF(AND($C8="Pre",$R8="Sí"),$N8,"") -> 5
A9: S-01 | B9: SUJ-01 | C9: Pre | D9: A | E9: 46258 | F9: 8 | G9: 08 | H9: D | I9: 90 | J9: No | K9: no, todos vienen de una declaración | L9: proyecto-gamma/opencode.json | M9: Incorrecta | N9: 3 | O9: Sí | P9: Sí | Q9: No | R9: Sí | T9: =IF(AND(AND($C9="Pre",$R9="Sí"),$H9="A"),$I9,"") | U9: =IF(AND(AND($C9="Pre",$R9="Sí"),$H9="B"),$I9,"") | V9: =IF(AND(AND($C9="Pre",$R9="Sí"),$H9="C"),$I9,"") | W9: =IF(AND(AND($C9="Pre",$R9="Sí"),$H9="D"),$I9,"") -> 90 | X9: =IF(AND($C9="Pre",$R9="Sí"),$I9,"") -> 90 | Y9: =IF(AND($C9="Post",$R9="Sí"),$I9,"") | Z9: =IF(AND(AND($C9="Pre",$R9="Sí"),$P9="Sí"),$I9,"") -> 90 | AA9: =IF(AND(AND($C9="Pre",$R9="Sí"),$P9="Parcial"),$I9,"") | AB9: =IF(AND(AND($C9="Pre",$R9="Sí"),$P9="No"),$I9,"") | AC9: =IF(AND(AND($C9="Pre",$R9="Sí"),$F9<=4),$I9,"") | AD9: =IF(AND(AND($C9="Pre",$R9="Sí"),$F9>=5),$I9,"") -> 90 | AE9: =IF(AND($C9="Pre",$R9="Sí"),$N9,"") -> 3
A10: S-02 | B10: SUJ-02 | C10: Pre | D10: A | E10: 46259 | F10: 1 | G10: 02 | H10: A | I10: 31 | J10: No | K10: MODELO-A-PROBADOR | L10: configuración global | M10: Correcta | N10: 1 | O10: Sí | P10: No | Q10: No | R10: Sí | T10: =IF(AND(AND($C10="Pre",$R10="Sí"),$H10="A"),$I10,"") -> 31 | U10: =IF(AND(AND($C10="Pre",$R10="Sí"),$H10="B"),$I10,"") | V10: =IF(AND(AND($C10="Pre",$R10="Sí"),$H10="C"),$I10,"") | W10: =IF(AND(AND($C10="Pre",$R10="Sí"),$H10="D"),$I10,"") | X10: =IF(AND($C10="Pre",$R10="Sí"),$I10,"") -> 31 | Y10: =IF(AND($C10="Post",$R10="Sí"),$I10,"") | Z10: =IF(AND(AND($C10="Pre",$R10="Sí"),$P10="Sí"),$I10,"") | AA10: =IF(AND(AND($C10="Pre",$R10="Sí"),$P10="Parcial"),$I10,"") | AB10: =IF(AND(AND($C10="Pre",$R10="Sí"),$P10="No"),$I10,"") -> 31 | AC10: =IF(AND(AND($C10="Pre",$R10="Sí"),$F10<=4),$I10,"") -> 31 | AD10: =IF(AND(AND($C10="Pre",$R10="Sí"),$F10>=5),$I10,"") | AE10: =IF(AND($C10="Pre",$R10="Sí"),$N10,"") -> 1
A11: S-02 | B11: SUJ-02 | C11: Pre | D11: A | E11: 46259 | F11: 2 | G11: 04 | H11: B | I11: 133 | J11: No | K11: MODELO-A-REFACT-PAGOS | L11: modulo-pagos/opencode.json | M11: Correcta | N11: 2 | O11: No | P11: No | Q11: No | R11: Sí | T11: =IF(AND(AND($C11="Pre",$R11="Sí"),$H11="A"),$I11,"") | U11: =IF(AND(AND($C11="Pre",$R11="Sí"),$H11="B"),$I11,"") -> 133 | V11: =IF(AND(AND($C11="Pre",$R11="Sí"),$H11="C"),$I11,"") | W11: =IF(AND(AND($C11="Pre",$R11="Sí"),$H11="D"),$I11,"") | X11: =IF(AND($C11="Pre",$R11="Sí"),$I11,"") -> 133 | Y11: =IF(AND($C11="Post",$R11="Sí"),$I11,"") | Z11: =IF(AND(AND($C11="Pre",$R11="Sí"),$P11="Sí"),$I11,"") | AA11: =IF(AND(AND($C11="Pre",$R11="Sí"),$P11="Parcial"),$I11,"") | AB11: =IF(AND(AND($C11="Pre",$R11="Sí"),$P11="No"),$I11,"") -> 133 | AC11: =IF(AND(AND($C11="Pre",$R11="Sí"),$F11<=4),$I11,"") -> 133 | AD11: =IF(AND(AND($C11="Pre",$R11="Sí"),$F11>=5),$I11,"") | AE11: =IF(AND($C11="Pre",$R11="Sí"),$N11,"") -> 2
A12: S-02 | B12: SUJ-02 | C12: Pre | D12: A | E12: 46259 | F12: 3 | G12: 06 | H12: C | I12: 177 | J12: No | K12: sí, está vigente | L12: se suma a la del proyecto | M12: Incorrecta | N12: 6 | O12: No | P12: No | Q12: No | R12: Sí | T12: =IF(AND(AND($C12="Pre",$R12="Sí"),$H12="A"),$I12,"") | U12: =IF(AND(AND($C12="Pre",$R12="Sí"),$H12="B"),$I12,"") | V12: =IF(AND(AND($C12="Pre",$R12="Sí"),$H12="C"),$I12,"") -> 177 | W12: =IF(AND(AND($C12="Pre",$R12="Sí"),$H12="D"),$I12,"") | X12: =IF(AND($C12="Pre",$R12="Sí"),$I12,"") -> 177 | Y12: =IF(AND($C12="Post",$R12="Sí"),$I12,"") | Z12: =IF(AND(AND($C12="Pre",$R12="Sí"),$P12="Sí"),$I12,"") | AA12: =IF(AND(AND($C12="Pre",$R12="Sí"),$P12="Parcial"),$I12,"") | AB12: =IF(AND(AND($C12="Pre",$R12="Sí"),$P12="No"),$I12,"") -> 177 | AC12: =IF(AND(AND($C12="Pre",$R12="Sí"),$F12<=4),$I12,"") -> 177 | AD12: =IF(AND(AND($C12="Pre",$R12="Sí"),$F12>=5),$I12,"") | AE12: =IF(AND($C12="Pre",$R12="Sí"),$N12,"") -> 6
A13: S-02 | B13: SUJ-02 | C13: Pre | D13: A | E13: 46259 | F13: 4 | G13: 08 | H13: D | I13: 300 | J13: Sí | K13: — | L13: — | M13: No resuelta | N13: 4 | O13: No | P13: No | Q13: No | R13: Sí | T13: =IF(AND(AND($C13="Pre",$R13="Sí"),$H13="A"),$I13,"") | U13: =IF(AND(AND($C13="Pre",$R13="Sí"),$H13="B"),$I13,"") | V13: =IF(AND(AND($C13="Pre",$R13="Sí"),$H13="C"),$I13,"") | W13: =IF(AND(AND($C13="Pre",$R13="Sí"),$H13="D"),$I13,"") -> 300 | X13: =IF(AND($C13="Pre",$R13="Sí"),$I13,"") -> 300 | Y13: =IF(AND($C13="Post",$R13="Sí"),$I13,"") | Z13: =IF(AND(AND($C13="Pre",$R13="Sí"),$P13="Sí"),$I13,"") | AA13: =IF(AND(AND($C13="Pre",$R13="Sí"),$P13="Parcial"),$I13,"") | AB13: =IF(AND(AND($C13="Pre",$R13="Sí"),$P13="No"),$I13,"") -> 300 | AC13: =IF(AND(AND($C13="Pre",$R13="Sí"),$F13<=4),$I13,"") -> 300 | AD13: =IF(AND(AND($C13="Pre",$R13="Sí"),$F13>=5),$I13,"") | AE13: =IF(AND($C13="Pre",$R13="Sí"),$N13,"") -> 4
... A65: S-08 | B65: SUJ-08 | C65: Pre | D65: A | E65: 46265 | F65: 8 | G65: 01 | H65: A | I65: 18 | J65: No | K65: MODELO-A-DOCUMENTADOR | L65: AGENTS.md del proyecto | M65: Incorrecta | N65: 1 | O65: No | P65: Parcial | Q65: No | R65: Sí | T65: =IF(AND(AND($C65="Pre",$R65="Sí"),$H65="A"),$I65,"") -> 18 | U65: =IF(AND(AND($C65="Pre",$R65="Sí"),$H65="B"),$I65,"") | V65: =IF(AND(AND($C65="Pre",$R65="Sí"),$H65="C"),$I65,"") | W65: =IF(AND(AND($C65="Pre",$R65="Sí"),$H65="D"),$I65,"") | X65: =IF(AND($C65="Pre",$R65="Sí"),$I65,"") -> 18 | Y65: =IF(AND($C65="Post",$R65="Sí"),$I65,"") | Z65: =IF(AND(AND($C65="Pre",$R65="Sí"),$P65="Sí"),$I65,"") | AA65: =IF(AND(AND($C65="Pre",$R65="Sí"),$P65="Parcial"),$I65,"") -> 18 | AB65: =IF(AND(AND($C65="Pre",$R65="Sí"),$P65="No"),$I65,"") | AC65: =IF(AND(AND($C65="Pre",$R65="Sí"),$F65<=4),$I65,"") | AD65: =IF(AND(AND($C65="Pre",$R65="Sí"),$F65>=5),$I65,"") -> 18 | AE65: =IF(AND($C65="Pre",$R65="Sí"),$N65,"") -> 1
